Workbook
Name Slicer_Region: #N/A
Name Slicer_Segment: #N/A
Name Slicer_warehouse_name: #N/A

Sheet Superstore raw data
A1: Row ID | B1: Order ID | C1: Order Date | D1: Ship Date | E1: Ship Mode | F1: Customer ID | G1: Customer Name | H1: Segment | I1: Country | J1: City | K1: State | L1: Postal Code | M1: Region | N1: Product ID | O1: Category | P1: Sub-Category | Q1: Product Name | R1: Sales | S1: Quantity | T1: Discount | U1: Profit | V1: P/L | W1: warehouse category | X1: warehouse name | Y1: Product Manager
A2: 1 | B2: CA-2016-152156 | C2: 42682 | D2: 42685 | E2: Second Class | F2: CG-12520 | G2: Claire Gute | H2: Consumer | I2: United States | J2: Henderson | K2: Kentucky | L2: 42420 | M2: South | N2: FUR-BO-10001798 | O2: Furniture | P2: Bookcases | Q2: Bush Somerset Collection Bookcase | R2: 261.96 | S2: 2 | T2: 0 | U2: 41.9136 | V2: =IF(U2>=0,"Profit","Loss") -> Profit | W2: =MID(B2,1,2) -> CA | X2: =IF(W2="CA","California","Texas") -> California | Y2: =VLOOKUP(P2,'Product manager data'!$A$1:B18,2,0) -> Tim Collins
A3: 2 | B3: CA-2016-152156 | C3: 42682 | D3: 42685 | E3: Second Class | F3: CG-12520 | G3: Claire Gute | H3: Consumer | I3: United States | J3: Henderson | K3: Kentucky | L3: 42420 | M3: South | N3: FUR-CH-10000454 | O3: Furniture | P3: Chairs | Q3: Hon Deluxe Fabric Upholstered Stacking Chairs, Rounded Back | R3: 731.94 | S3: 3 | T3: 0 | U3: 219.582 | V3: =IF(U3>=0,"Profit","Loss") -> Profit | W3: =MID(B3,1,2) -> CA | X3: =IF(W3="CA","California","Texas") -> California | Y3: =VLOOKUP(P3,'Product manager data'!$A$1:B19,2,0) -> Sandra Cruz
A4: 3 | B4: CA-2016-138688 | C4: 42533 | D4: 42537 | E4: Second Class | F4: DV-13045 | G4: Darrin Van Huff | H4: Corporate | I4: United States | J4: Los Angeles | K4: California | L4: 90036 | M4: West | N4: OFF-LA-10000240 | O4: Office Supplies | P4: Labels | Q4: Self-Adhesive Address Labels for Typewriters by Universal | R4: 14.62 | S4: 2 | T4: 0 | U4: 6.8714 | V4: =IF(U4>=0,"Profit","Loss") -> Profit | W4: =MID(B4,1,2) -> CA | X4: =IF(W4="CA","California","Texas") -> California | Y4: =VLOOKUP(P4,'Product manager data'!$A$1:B20,2,0) -> Willie Zensen
A5: 4 | B5: US-2015-108966 | C5: 42288 | D5: 42295 | E5: Standard Class | F5: SO-20335 | G5: Sean O'Donnell | H5: Consumer | I5: United States | J5: Fort Lauderdale | K5: Florida | L5: 33311 | M5: South | N5: FUR-TA-10000577 | O5: Furniture | P5: Tables | Q5: Bretford CR4500 Series Slim Rectangular Table | R5: 957.5775 | S5: 5 | T5: 0.45 | U5: -383.031 | V5: =IF(U5>=0,"Profit","Loss") -> Loss | W5: =MID(B5,1,2) -> US | X5: =IF(W5="CA","California","Texas") -> Texas | Y5: =VLOOKUP(P5,'Product manager data'!$A$1:B21,2,0) -> Michael Benoit
A6: 5 | B6: US-2015-108966 | C6: 42288 | D6: 42295 | E6: Standard Class | F6: SO-20335 | G6: Sean O'Donnell | H6: Consumer | I6: United States | J6: Fort Lauderdale | K6: Florida | L6: 33311 | M6: South | N6: OFF-ST-10000760 | O6: Office Supplies | P6: Storage | Q6: Eldon Fold 'N Roll Cart System | R6: 22.368 | S6: 2 | T6: 0.2 | U6: 2.5164 | V6: =IF(U6>=0,"Profit","Loss") -> Profit | W6: =MID(B6,1,2) -> US | X6: =IF(W6="CA","California","Texas") -> Texas | Y6: =VLOOKUP(P6,'Product manager data'!$A$1:B22,2,0) -> Myrtle Holloway
A7: 6 | B7: CA-2014-115812 | C7: 41799 | D7: 41804 | E7: Standard Class | F7: BH-11710 | G7: Brosina Hoffman | H7: Consumer | I7: United States | J7: Los Angeles | K7: California | L7: 90032 | M7: West | N7: FUR-FU-10001487 | O7: Furniture | P7: Furnishings | Q7: Eldon Expressions Wood and Plastic Desk Accessories, Cherry Wood | R7: 48.86 | S7: 7 | T7: 0 | U7: 14.1694 | V7: =IF(U7>=0,"Profit","Loss") -> Profit | W7: =MID(B7,1,2) -> CA | X7: =IF(W7="CA","California","Texas") -> California | Y7: =VLOOKUP(P7,'Product manager data'!$A$1:B23,2,0) -> Robin Dennis
A8: 7 | B8: CA-2014-115812 | C8: 41799 | D8: 41804 | E8: Standard Class | F8: BH-11710 | G8: Brosina Hoffman | H8: Consumer | I8: United States | J8: Los Angeles | K8: California | L8: 90032 | M8: West | N8: OFF-AR-10002833 | O8: Office Supplies | P8: Art | Q8: Newell 322 | R8: 7.28 | S8: 4 | T8: 0 | U8: 1.9656 | V8: =IF(U8>=0,"Profit","Loss") -> Profit | W8: =MID(B8,1,2) -> CA | X8: =IF(W8="CA","California","Texas") -> California | Y8: =VLOOKUP(P8,'Product manager data'!$A$1:B24,2,0) -> Eric Goetz
A9: 8 | B9: CA-2014-115812 | C9: 41799 | D9: 41804 | E9: Standard Class | F9: BH-11710 | G9: Brosina Hoffman | H9: Consumer | I9: United States | J9: Los Angeles | K9: California | L9: 90032 | M9: West | N9: TEC-PH-10002275 | O9: Technology | P9: Phones | Q9: Mitel 5320 IP Phone VoIP phone | R9: 907.152 | S9: 6 | T9: 0.2 | U9: 90.7152 | V9: =IF(U9>=0,"Profit","Loss") -> Profit | W9: =MID(B9,1,2) -> CA | X9: =IF(W9="CA","California","Texas") -> California | Y9: =VLOOKUP(P9,'Product manager data'!$A$1:B25,2,0) -> James Marez
A10: 9 | B10: CA-2014-115812 | C10: 41799 | D10: 41804 | E10: Standard Class | F10: BH-11710 | G10: Brosina Hoffman | H10: Consumer | I10: United States | J10: Los Angeles | K10: California | L10: 90032 | M10: West | N10: OFF-BI-10003910 | O10: Office Supplies | P10: Binders | Q10: DXL Angle-View Binders with Locking Rings by Samsill | R10: 18.504 | S10: 3 | T10: 0.2 | U10: 5.7825 | V10: =IF(U10>=0,"Profit","Loss") -> Profit | W10: =MID(B10,1,2) -> CA | X10: =IF(W10="CA","California","Texas") -> California | Y10: =VLOOKUP(P10,'Product manager data'!$A$1:B26,2,0) -> Kimberly Harrington
A11: 10 | B11: CA-2014-115812 | C11: 41799 | D11: 41804 | E11: Standard Class | F11: BH-11710 | G11: Brosina Hoffman | H11: Consumer | I11: United States | J11: Los Angeles | K11: California | L11: 90032 | M11: West | N11: OFF-AP-10002892 | O11: Office Supplies | P11: Appliances | Q11: Belkin F5C206VTEL 6 Outlet Surge | R11: 114.9 | S11: 5 | T11: 0 | U11: 34.47 | V11: =IF(U11>=0,"Profit","Loss") -> Profit | W11: =MID(B11,1,2) -> CA | X11: =IF(W11="CA","California","Texas") -> California | Y11: =VLOOKUP(P11,'Product manager data'!$A$1:B27,2,0) -> Mary Wood
A12: 11 | B12: CA-2014-115812 | C12: 41799 | D12: 41804 | E12: Standard Class | F12: BH-11710 | G12: Brosina Hoffman | H12: Consumer | I12: United States | J12: Los Angeles | K12: California | L12: 90032 | M12: West | N12: FUR-TA-10001539 | O12: Furniture | P12: Tables | Q12: Chromcraft Rectangular Conference Tables | R12: 1706.184 | S12: 9 | T12: 0.2 | U12: 85.3092 | V12: =IF(U12>=0,"Profit","Loss") -> Profit | W12: =MID(B12,1,2) -> CA | X12: =IF(W12="CA","California","Texas") -> California | Y12: =VLOOKUP(P12,'Product manager data'!$A$1:B28,2,0) -> Michael Benoit
A13: 12 | B13: CA-2014-115812 | C13: 41799 | D13: 41804 | E13: Standard Class | F13: BH-11710 | G13: Brosina Hoffman | H13: Consumer | I13: United States | J13: Los Angeles | K13: California | L13: 90032 | M13: West | N13: TEC-PH-10002033 | O13: Technology | P13: Phones | Q13: Konftel 250 Conference†phone†- Charcoal black | R13: 911.424 | S13: 4 | T13: 0.2 | U13: 68.3568 | V13: =IF(U13>=0,"Profit","Loss") -> Profit | W13: =MID(B13,1,2) -> CA | X13: =IF(W13="CA","California","Texas") -> California | Y13: =VLOOKUP(P13,'Product manager data'!$A$1:B29,2,0) -> James Marez
... A9995: 9994 | B9995: CA-2017-119914 | C9995: 42859 | D9995: 42864 | E9995: Second Class | F9995: CC-12220 | G9995: Chris Cortes | H9995: Consumer | I9995: United States | J9995: Westminster | K9995: California | L9995: 92683 | M9995: West | N9995: OFF-AP-10002684 | O9995: Office Supplies | P9995: Appliances | Q9995: Acco 7-Outlet Masterpiece Power Center, Wihtout Fax/Phone Line Protection | R9995: 243.16 | S9995: 2 | T9995: 0 | U9995: 72.948 | V9995: =IF(U9995>=0,"Profit","Loss") -> Profit | W9995: =MID(B9995,1,2) -> CA | X9995: =IF(W9995="CA","California","Texas") -> California | Y9995: =VLOOKUP(P9995,'Product manager data'!$A$1:B10011,2,0) -> Mary Wood

Sheet Product manager data
A1: Sub-Category | B1: Product Managers
A2: Bookcases | B2: Tim Collins
A3: Chairs | B3: Sandra Cruz
A4: Labels | B4: Willie Zensen
A5: Tables | B5: Michael Benoit
A6: Storage | B6: Myrtle Holloway
A7: Furnishings | B7: Robin Dennis
A8: Art | B8: Eric Goetz
A9: Phones | B9: James Marez
A10: Binders | B10: Kimberly Harrington
A11: Appliances | B11: Mary Wood
A12: Paper | B12: Beth Higgins
... A18: Copiers | B18: Jason Lightner

Sheet Pivot Table
A3: Row Labels | B3: Sum of Sales
A4: Tables | B4: 206965.53
A5: Supplies | B5: 46673.538
A6: Storage | B6: 223843.61
A7: Phones | B7: 330007.05
A8: Paper | B8: 78479.206
A9: Machines | B9: 189238.63
A10: Labels | B10: 12486.312
A11: Furnishings | B11: 91705.164
A12: Fasteners | B12: 3024.28
A13: Envelopes | B13: 16476.402
A14: Copiers | B14: 149528.03
A15: Chairs | B15: 328449.1
... A21: Grand Total | B21: 2297200.9
A23: Row Labels | B23: Sum of Sales
A24: James Marez | B24: 330007.05
A25: Sandra Cruz | B25: 328449.1
A26: Myrtle Holloway | B26: 223843.61
A27: Michael Benoit | B27: 206965.53
A28: Kimberly Harrington | B28: 203412.73
A29: Jennifer Hutchins | B29: 189238.63
A30: Reggie Bacon | B30: 167380.32
A31: Jason Lightner | B31: 149528.03
A32: Tim Collins | B32: 114880
A33: Mary Wood | B33: 107532.16
A34: Robin Dennis | B34: 91705.164
A35: Beth Higgins | B35: 78479.206
... A41: Grand Total | B41: 2297200.9
A43: Row Labels | B43: Sum of Sales
A44: Furniture | B44: 0.32300171
A45: Office Supplies | B45: 0.31301008
A46: Technology | B46: 0.36398821
A47: Grand Total | B47: 1
A54: Row Labels | B54: Sum of Sales
A55: 2014
A56: Jan | B56: 13275.131
A57: Feb | B57: 5406.528
A58: Mar | B58: 50708.349
A59: Apr | B59: 30388.465
A60: May | B60: 22478.88
...

Sheet Sales dashboard
J3: Sales Dashboard
